Workbook

Sheet MULAI
A1: Bagian | B1: Petunjuk
A2: PROJECT NURA | B2: Kerangka data Work Order / SPK upper — versi penataan ulang, bukan release produksi.
A3: Status seluruh order | B3: DRAFT - PERLU VERIFIKASI. Kuantitas cocok; tanggal, UOM, ukuran, spesifikasi dan approval belum lengkap.
A4: 01 ADMIN_ORDER | B4: Satu baris per order. Filter berdasarkan build, artikel, tujuan atau status. Kolom kuning diisi setelah diverifikasi.
A5: 02 SIZE_RUN | B5: Satu baris per order; 29 ukuran sumber dipertahankan. Total ukuran mencakup SEMUA kolom ukuran.
A6: 03 KARTU_OPERATOR | B6: 59 kartu, masing-masing satu halaman cetak A4. Bagian atas menampilkan status; target upper belum diisi, jadwal assembling hanya referensi.
A7: 04 KESIAPAN | B7: Isian admin untuk unit, sistem ukuran, BOM, tech pack, batch dan otorisasi. Tidak ada persetujuan yang diasumsikan.
A8: 05 AKTUAL | B8: Template pencatatan hasil produksi per transaksi/bundle. Tambahkan baris baru untuk transaksi berikutnya; jangan menimpa riwayat.
A9: 06 KONFIRMASI | B9: Daftar konflik/istilah yang harus dijelaskan dan diputuskan oleh pihak berwenang.
A10: 07 SUMBER_ORDER | B10: Nilai asli dari dua sheet untuk penelusuran, termasuk tanggal Juli. Bukan instruksi kerja aktif.
A11: 08 KAMUS | B11: Arti kolom dan aturan pengisian. Istilah yang belum jelas tetap ditandai perlu konfirmasi.
A12: Warna | B12: Biru: data sumber / hasil hitung; kuning: isian verifikasi admin; merah muda: masalah / status draft. Warna selalu disertai label.
... A18: Pengeditan | B18: Master admin/size merupakan sumber kartu. Kartu operator berformula: jangan ditimpa manual. Tambahan order baru memerlukan penambahan kartu dan formula terkait.

Sheet 01 ADMIN_ORDER
A1: No SPK sumber | B1: Build sumber | C1: Model | D1: Artikel | E1: PO sumber (teks) | F1: Penanda FGT | G1: Tujuan / channel sumber | H1: Warna | I1: Qty order (UOM belum pasti) | J1: Total size (hitung) | K1: Selisih size-order | L1: Rencana kirim material (SEP) | M1: Rencana assembly mulai (SEP) | N1: Rencana assembly selesai (SEP) | O1: PODD sumber (definisi belum pasti) | P1: Target mulai UPPER [ISI] | Q1: Target selesai UPPER [ISI] | R1: Status dokumen | S1: Catatan verifikasi
A2: 137/10/1 (59) | B2: A-19 | C2: FRONTCOURT LOW | D2: LA6616 | E2: 903285985 | F2: Tidak bertanda | G2: Morocco | H2: EARTH STRATA/OFF WHITE/DARK BROWN | I2: 155 | J2: ='02 SIZE_RUN'!AG2 -> 155 | K2: =J2-I2 -> 0 | L2: 46273 | M2: 46290 | N2: 46290 | O2: 46309 | R2: DRAFT - PERLU VERIFIKASI | S2: Tanggal detail Juli konflik; UOM/size/spec/approval belum diverifikasi.
A3: 138/10/2 (59) | B3: A-19 | C3: FRONTCOURT LOW | D3: LA6616 | E3: 903285985 (FGT) | F3: FGT | G3: Morocco | H3: EARTH STRATA/OFF WHITE/DARK BROWN | I3: 9 | J3: ='02 SIZE_RUN'!AG3 -> 9 | K3: =J3-I3 -> 0 | L3: 46273 | M3: 46290 | N3: 46290 | O3: 46309 | R3: DRAFT - PERLU VERIFIKASI | S3: Tanggal detail Juli konflik; UOM/size/spec/approval belum diverifikasi.
A4: 139/10/3 (59) | B4: A-19 | C4: FRONTCOURT LOW | D4: LA6616 | E4: 903424679 | F4: Tidak bertanda | G4: Germany | H4: EARTH STRATA/OFF WHITE/DARK BROWN | I4: 650 | J4: ='02 SIZE_RUN'!AG4 -> 650 | K4: =J4-I4 -> 0 | L4: 46273 | M4: 46290 | N4: 46290 | O4: 46309 | R4: DRAFT - PERLU VERIFIKASI | S4: Tanggal detail Juli konflik; UOM/size/spec/approval belum diverifikasi.
A5: 140/10/4 (59) | B5: A-19 | C5: FRONTCOURT LOW | D5: LA6616 | E5: 903424725 | F5: Tidak bertanda | G5: Germany | H5: EARTH STRATA/OFF WHITE/DARK BROWN | I5: 650 | J5: ='02 SIZE_RUN'!AG5 -> 650 | K5: =J5-I5 -> 0 | L5: 46273 | M5: 46290 | N5: 46293 | O5: 46309 | R5: DRAFT - PERLU VERIFIKASI | S5: Tanggal detail Juli konflik; UOM/size/spec/approval belum diverifikasi.
A6: 141/10/5 (59) | B6: A-19 | C6: FRONTCOURT LOW | D6: LA6617 | E6: 903271565 | F6: Tidak bertanda | G6: Morocco | H6: OLIVE TWO/OFF WHITE/OLIVE THREE | I6: 181 | J6: ='02 SIZE_RUN'!AG6 -> 181 | K6: =J6-I6 -> 0 | L6: 46273 | M6: 46293 | N6: 46293 | O6: 46309 | R6: DRAFT - PERLU VERIFIKASI | S6: Tanggal detail Juli konflik; UOM/size/spec/approval belum diverifikasi.
A7: 142/10/6 (59) | B7: A-19 | C7: FRONTCOURT LOW | D7: LA6617 | E7: 903271565 (FGT) | F7: FGT | G7: Morocco | H7: OLIVE TWO/OFF WHITE/OLIVE THREE | I7: 9 | J7: ='02 SIZE_RUN'!AG7 -> 9 | K7: =J7-I7 -> 0 | L7: 46273 | M7: 46293 | N7: 46293 | O7: 46309 | R7: DRAFT - PERLU VERIFIKASI | S7: Tanggal detail Juli konflik; UOM/size/spec/approval belum diverifikasi.
A8: 143/10/7 (59) | B8: A-19 | C8: FRONTCOURT LOW | D8: LA6617 | E8: 903079277 | F8: Tidak bertanda | G8: USA | H8: OLIVE TWO/OFF WHITE/OLIVE THREE | I8: 6120 | J8: ='02 SIZE_RUN'!AG8 -> 6120 | K8: =J8-I8 -> 0 | L8: 46273 | M8: 46293 | N8: 46302 | O8: 46309 | R8: DRAFT - PERLU VERIFIKASI | S8: Tanggal detail Juli konflik; UOM/size/spec/approval belum diverifikasi.
A9: 144/10/8 (59) | B9: A-19 | C9: FRONTCOURT LOW | D9: LA6606 | E9: 903279874 | F9: Tidak bertanda | G9: Peru | H9: CORE BLACK/CORE BLACK/GREY FIVE | I9: 440 | J9: ='02 SIZE_RUN'!AG9 -> 440 | K9: =J9-I9 -> 0 | L9: 46280 | M9: 46302 | N9: 46302 | O9: 46309 | R9: DRAFT - PERLU VERIFIKASI | S9: Tanggal detail Juli konflik; UOM/size/spec/approval belum diverifikasi.
A10: 145/10/9 (59) | B10: A-19 | C10: FRONTCOURT LOW | D10: LA6606 | E10: 903279874 (FGT) | F10: FGT | G10: Peru | H10: CORE BLACK/CORE BLACK/GREY FIVE | I10: 9 | J10: ='02 SIZE_RUN'!AG10 -> 9 | K10: =J10-I10 -> 0 | L10: 46280 | M10: 46302 | N10: 46302 | O10: 46309 | R10: DRAFT - PERLU VERIFIKASI | S10: Tanggal detail Juli konflik; UOM/size/spec/approval belum diverifikasi.
A11: 146/10/10 (59) | B11: A-19 | C11: FRONTCOURT LOW | D11: LA6606 | E11: 903284277 | F11: Tidak bertanda | G11: Germany (Zalando) | H11: CORE BLACK/CORE BLACK/GREY FIVE | I11: 645 | J11: ='02 SIZE_RUN'!AG11 -> 645 | K11: =J11-I11 -> 0 | L11: 46280 | M11: 46302 | N11: 46303 | O11: 46309 | R11: DRAFT - PERLU VERIFIKASI | S11: Tanggal detail Juli konflik; UOM/size/spec/approval belum diverifikasi.
A12: 147/10/11 (59) | B12: A-19 | C12: FRONTCOURT LOW | D12: LA6604 | E12: 903410228 | F12: Tidak bertanda | G12: Israel | H12: CORE BLACK/FTWR WHITE/CORE BLACK | I12: 241 | J12: ='02 SIZE_RUN'!AG12 -> 241 | K12: =J12-I12 -> 0 | L12: 46280 | M12: 46303 | N12: 46303 | O12: 46317 | R12: DRAFT - PERLU VERIFIKASI | S12: Tanggal detail Juli konflik; UOM/size/spec/approval belum diverifikasi.
A13: 148/10/12 (59) | B13: A-19 | C13: FRONTCOURT LOW | D13: LA6604 | E13: 903410228 (FGT) | F13: FGT | G13: Israel | H13: CORE BLACK/FTWR WHITE/CORE BLACK | I13: 9 | J13: ='02 SIZE_RUN'!AG13 -> 9 | K13: =J13-I13 -> 0 | L13: 46280 | M13: 46303 | N13: 46303 | O13: 46317 | R13: DRAFT - PERLU VERIFIKASI | S13: Tanggal detail Juli konflik; UOM/size/spec/approval belum diverifikasi.
... A60: 195/10/59 (59) | B60: B-19 | C60: FRONTCOURT LOW | D60: LA6615 | E60: 903500993 (FGT) | F60: FGT | G60: Germany | H60: FTWR WHITE/CORE BLACK/GREY ONE | I60: 9 | J60: ='02 SIZE_RUN'!AG60 -> 9 | K60: =J60-I60 -> 0 | L60: 46289 | M60: 46317 | N60: 46317 | O60: 46332 | R60: DRAFT - PERLU VERIFIKASI | S60: Tanggal detail Juli konflik; UOM/size/spec/approval belum diverifikasi.

Sheet 02 SIZE_RUN
A1: No SPK sumber | B1: Artikel | C1: Qty order | D1: 3 | E1: 3- | F1: 4 | G1: 4- | H1: 5 | I1: 5- | J1: 6 | K1: 6- | L1: 7 | M1: 7- | N1: 8 | O1: 8- | P1: 9 | Q1: 9- | R1: 10 | S1: 10- | T1: 11 | U1: 11- | V1: 12 | W1: 12- | X1: 13 | Y1: 13- | Z1: 14 | AA1: 14- | AB1: 15 | AC1: 15- | AD1: 16 | AE1: 17 | AF1: 18 | AG1: Total semua size | AH1: Selisih | AI1: Hasil cek
A2: 137/10/1 (59) | B2: LA6616 | C2: 155 | D2: 0 | E2: 0 | F2: 0 | G2: 0 | H2: 0 | I2: 0 | J2: 0 | K2: 0 | L2: 10 | M2: 10 | N2: 25 | O2: 25 | P2: 35 | Q2: 20 | R2: 10 | S2: 10 | T2: 5 | U2: 0 | V2: 5 | W2: 0 | X2: 0 | Y2: 0 | Z2: 0 | AA2: 0 | AB2: 0 | AC2: 0 | AD2: 0 | AE2: 0 | AF2: 0 | AG2: =SUM(D2:AF2) -> 155 | AH2: =AG2-C2 -> 0 | AI2: =IF(AH2=0,"COCOK","CEK SELISIH") -> COCOK
A3: 138/10/2 (59) | B3: LA6616 | C3: 9 | D3: 0 | E3: 0 | F3: 0 | G3: 0 | H3: 0 | I3: 0 | J3: 0 | K3: 0 | L3: 0 | M3: 0 | N3: 0 | O3: 9 | P3: 0 | Q3: 0 | R3: 0 | S3: 0 | T3: 0 | U3: 0 | V3: 0 | W3: 0 | X3: 0 | Y3: 0 | Z3: 0 | AA3: 0 | AB3: 0 | AC3: 0 | AD3: 0 | AE3: 0 | AF3: 0 | AG3: =SUM(D3:AF3) -> 9 | AH3: =AG3-C3 -> 0 | AI3: =IF(AH3=0,"COCOK","CEK SELISIH") -> COCOK
A4: 139/10/3 (59) | B4: LA6616 | C4: 650 | D4: 0 | E4: 0 | F4: 0 | G4: 0 | H4: 0 | I4: 0 | J4: 6 | K4: 10 | L4: 23 | M4: 29 | N4: 81 | O4: 72 | P4: 117 | Q4: 88 | R4: 78 | S4: 71 | T4: 49 | U4: 0 | V4: 26 | W4: 0 | X4: 0 | Y4: 0 | Z4: 0 | AA4: 0 | AB4: 0 | AC4: 0 | AD4: 0 | AE4: 0 | AF4: 0 | AG4: =SUM(D4:AF4) -> 650 | AH4: =AG4-C4 -> 0 | AI4: =IF(AH4=0,"COCOK","CEK SELISIH") -> COCOK
A5: 140/10/4 (59) | B5: LA6616 | C5: 650 | D5: 0 | E5: 0 | F5: 0 | G5: 0 | H5: 0 | I5: 0 | J5: 10 | K5: 32 | L5: 36 | M5: 36 | N5: 107 | O5: 49 | P5: 130 | Q5: 62 | R5: 71 | S5: 52 | T5: 36 | U5: 0 | V5: 29 | W5: 0 | X5: 0 | Y5: 0 | Z5: 0 | AA5: 0 | AB5: 0 | AC5: 0 | AD5: 0 | AE5: 0 | AF5: 0 | AG5: =SUM(D5:AF5) -> 650 | AH5: =AG5-C5 -> 0 | AI5: =IF(AH5=0,"COCOK","CEK SELISIH") -> COCOK
A6: 141/10/5 (59) | B6: LA6617 | C6: 181 | D6: 0 | E6: 0 | F6: 0 | G6: 0 | H6: 0 | I6: 0 | J6: 2 | K6: 2 | L6: 7 | M6: 15 | N6: 32 | O6: 24 | P6: 33 | Q6: 22 | R6: 14 | S6: 14 | T6: 7 | U6: 2 | V6: 7 | W6: 0 | X6: 0 | Y6: 0 | Z6: 0 | AA6: 0 | AB6: 0 | AC6: 0 | AD6: 0 | AE6: 0 | AF6: 0 | AG6: =SUM(D6:AF6) -> 181 | AH6: =AG6-C6 -> 0 | AI6: =IF(AH6=0,"COCOK","CEK SELISIH") -> COCOK
A7: 142/10/6 (59) | B7: LA6617 | C7: 9 | D7: 0 | E7: 0 | F7: 0 | G7: 0 | H7: 0 | I7: 0 | J7: 0 | K7: 0 | L7: 0 | M7: 0 | N7: 0 | O7: 9 | P7: 0 | Q7: 0 | R7: 0 | S7: 0 | T7: 0 | U7: 0 | V7: 0 | W7: 0 | X7: 0 | Y7: 0 | Z7: 0 | AA7: 0 | AB7: 0 | AC7: 0 | AD7: 0 | AE7: 0 | AF7: 0 | AG7: =SUM(D7:AF7) -> 9 | AH7: =AG7-C7 -> 0 | AI7: =IF(AH7=0,"COCOK","CEK SELISIH") -> COCOK
A8: 143/10/7 (59) | B8: LA6617 | C8: 6120 | D8: 0 | E8: 0 | F8: 0 | G8: 0 | H8: 0 | I8: 0 | J8: 0 | K8: 0 | L8: 420 | M8: 530 | N8: 550 | O8: 700 | P8: 740 | Q8: 730 | R8: 710 | S8: 720 | T8: 0 | U8: 600 | V8: 0 | W8: 420 | X8: 0 | Y8: 0 | Z8: 0 | AA8: 0 | AB8: 0 | AC8: 0 | AD8: 0 | AE8: 0 | AF8: 0 | AG8: =SUM(D8:AF8) -> 6120 | AH8: =AG8-C8 -> 0 | AI8: =IF(AH8=0,"COCOK","CEK SELISIH") -> COCOK
A9: 144/10/8 (59) | B9: LA6606 | C9: 440 | D9: 0 | E9: 0 | F9: 0 | G9: 0 | H9: 0 | I9: 0 | J9: 0 | K9: 0 | L9: 37 | M9: 73 | N9: 92 | O9: 73 | P9: 73 | Q9: 55 | R9: 37 | S9: 0 | T9: 0 | U9: 0 | V9: 0 | W9: 0 | X9: 0 | Y9: 0 | Z9: 0 | AA9: 0 | AB9: 0 | AC9: 0 | AD9: 0 | AE9: 0 | AF9: 0 | AG9: =SUM(D9:AF9) -> 440 | AH9: =AG9-C9 -> 0 | AI9: =IF(AH9=0,"COCOK","CEK SELISIH") -> COCOK
A10: 145/10/9 (59) | B10: LA6606 | C10: 9 | D10: 0 | E10: 0 | F10: 0 | G10: 0 | H10: 0 | I10: 0 | J10: 0 | K10: 0 | L10: 0 | M10: 0 | N10: 0 | O10: 9 | P10: 0 | Q10: 0 | R10: 0 | S10: 0 | T10: 0 | U10: 0 | V10: 0 | W10: 0 | X10: 0 | Y10: 0 | Z10: 0 | AA10: 0 | AB10: 0 | AC10: 0 | AD10: 0 | AE10: 0 | AF10: 0 | AG10: =SUM(D10:AF10) -> 9 | AH10: =AG10-C10 -> 0 | AI10: =IF(AH10=0,"COCOK","CEK SELISIH") -> COCOK
A11: 146/10/10 (59) | B11: LA6606 | C11: 645 | D11: 1 | E11: 12 | F11: 19 | G11: 33 | H11: 52 | I11: 57 | J11: 93 | K11: 49 | L11: 8 | M11: 9 | N11: 26 | O11: 23 | P11: 31 | Q11: 15 | R11: 8 | S11: 5 | T11: 4 | U11: 71 | V11: 71 | W11: 37 | X11: 0 | Y11: 21 | Z11: 0 | AA11: 0 | AB11: 0 | AC11: 0 | AD11: 0 | AE11: 0 | AF11: 0 | AG11: =SUM(D11:AF11) -> 645 | AH11: =AG11-C11 -> 0 | AI11: =IF(AH11=0,"COCOK","CEK SELISIH") -> COCOK
A12: 147/10/11 (59) | B12: LA6604 | C12: 241 | D12: 0 | E12: 0 | F12: 0 | G12: 0 | H12: 0 | I12: 0 | J12: 0 | K12: 24 | L12: 1 | M12: 20 | N12: 50 | O12: 19 | P12: 32 | Q12: 26 | R12: 22 | S12: 19 | T12: 19 | U12: 0 | V12: 9 | W12: 0 | X12: 0 | Y12: 0 | Z12: 0 | AA12: 0 | AB12: 0 | AC12: 0 | AD12: 0 | AE12: 0 | AF12: 0 | AG12: =SUM(D12:AF12) -> 241 | AH12: =AG12-C12 -> 0 | AI12: =IF(AH12=0,"COCOK","CEK SELISIH") -> COCOK
A13: 148/10/12 (59) | B13: LA6604 | C13: 9 | D13: 0 | E13: 0 | F13: 0 | G13: 0 | H13: 0 | I13: 0 | J13: 0 | K13: 0 | L13: 0 | M13: 0 | N13: 0 | O13: 9 | P13: 0 | Q13: 0 | R13: 0 | S13: 0 | T13: 0 | U13: 0 | V13: 0 | W13: 0 | X13: 0 | Y13: 0 | Z13: 0 | AA13: 0 | AB13: 0 | AC13: 0 | AD13: 0 | AE13: 0 | AF13: 0 | AG13: =SUM(D13:AF13) -> 9 | AH13: =AG13-C13 -> 0 | AI13: =IF(AH13=0,"COCOK","CEK SELISIH") -> COCOK
... A60: 195/10/59 (59) | B60: LA6615 | C60: 9 | D60: 0 | E60: 0 | F60: 0 | G60: 0 | H60: 0 | I60: 0 | J60: 0 | K60: 0 | L60: 0 | M60: 0 | N60: 0 | O60: 9 | P60: 0 | Q60: 0 | R60: 0 | S60: 0 | T60: 0 | U60: 0 | V60: 0 | W60: 0 | X60: 0 | Y60: 0 | Z60: 0 | AA60: 0 | AB60: 0 | AC60: 0 | AD60: 0 | AE60: 0 | AF60: 0 | AG60: =SUM(D60:AF60) -> 9 | AH60: =AG60-C60 -> 0 | AI60: =IF(AH60=0,"COCOK","CEK SELISIH") -> COCOK

Sheet 03 KARTU_OPERATOR
A1: PROJECT NURA — KARTU KERJA UPPER
A2: ='01 ADMIN_ORDER'!R2 -> DRAFT - PERLU VERIFIKASI
A3: Belum untuk instruksi produksi sampai data dan otorisasi diverifikasi.
A4: NO SPK | C4: ='01 ADMIN_ORDER'!A2 -> 137/10/1 (59)
A5: MODEL / ARTIKEL | C5: ='01 ADMIN_ORDER'!C2&" / "&'01 ADMIN_ORDER'!D2 -> FRONTCOURT LOW / LA6616
A6: PO SUMBER | C6: ='01 ADMIN_ORDER'!E2 -> 903285985
A7: WARNA | C7: ='01 ADMIN_ORDER'!H2 -> EARTH STRATA/OFF WHITE/DARK BROWN
A8: BUILD / TUJUAN | C8: ='01 ADMIN_ORDER'!B2&" / "&'01 ADMIN_ORDER'!G2 -> A-19 / Morocco
A9: QTY / UOM | C9: ='01 ADMIN_ORDER'!I2&" / "&IF('04 KESIAPAN'!B2="","UOM BELUM DIISI",'04 KESIAPAN'!B2) -> 155 / UOM BELUM DIISI
A10: =IF('04 KESIAPAN'!C2="","SISTEM UKURAN BELUM DIISI",'04 KESIAPAN'!C2)&" | Tanda -: "&IF('04 KESIAPAN'!D2="","BELUM DIKONFIRMASI",'04 KESIAPAN'!D2) -> SISTEM UKURAN BELUM DIISI | Tanda -: BELUM DIKONFIRMASI
A11: DISTRIBUSI UKURAN — label sumber; qty nol = tidak ada alokasi pada sumber
A12: 3 | B12: ='02 SIZE_RUN'!D2 -> 0 | C12: 3- | D12: ='02 SIZE_RUN'!E2 -> 0 | E12: 4 | F12: ='02 SIZE_RUN'!F2 -> 0 | G12: 4- | H12: ='02 SIZE_RUN'!G2 -> 0
A13: 5 | B13: ='02 SIZE_RUN'!H2 -> 0 | C13: 5- | D13: ='02 SIZE_RUN'!I2 -> 0 | E13: 6 | F13: ='02 SIZE_RUN'!J2 -> 0 | G13: 6- | H13: ='02 SIZE_RUN'!K2 -> 0
A14: 7 | B14: ='02 SIZE_RUN'!L2 -> 10 | C14: 7- | D14: ='02 SIZE_RUN'!M2 -> 10 | E14: 8 | F14: ='02 SIZE_RUN'!N2 -> 25 | G14: 8- | H14: ='02 SIZE_RUN'!O2 -> 25
A15: 9 | B15: ='02 SIZE_RUN'!P2 -> 35 | C15: 9- | D15: ='02 SIZE_RUN'!Q2 -> 20 | E15: 10 | F15: ='02 SIZE_RUN'!R2 -> 10 | G15: 10- | H15: ='02 SIZE_RUN'!S2 -> 10
A16: 11 | B16: ='02 SIZE_RUN'!T2 -> 5 | C16: 11- | D16: ='02 SIZE_RUN'!U2 -> 0 | E16: 12 | F16: ='02 SIZE_RUN'!V2 -> 5 | G16: 12- | H16: ='02 SIZE_RUN'!W2 -> 0
A17: 13 | B17: ='02 SIZE_RUN'!X2 -> 0 | C17: 13- | D17: ='02 SIZE_RUN'!Y2 -> 0 | E17: 14 | F17: ='02 SIZE_RUN'!Z2 -> 0 | G17: 14- | H17: ='02 SIZE_RUN'!AA2 -> 0
A18: 15 | B18: ='02 SIZE_RUN'!AB2 -> 0 | C18: 15- | D18: ='02 SIZE_RUN'!AC2 -> 0 | E18: 16 | F18: ='02 SIZE_RUN'!AD2 -> 0 | G18: 17 | H18: ='02 SIZE_RUN'!AE2 -> 0
A19: 18 | B19: ='02 SIZE_RUN'!AF2 -> 0
A20: ="TOTAL SIZE: "&'02 SIZE_RUN'!AG2&" | SELISIH: "&'02 SIZE_RUN'!AH2 -> TOTAL SIZE: 155 | SELISIH: 0
A21: TARGET MULAI UPPER | D21: =IF('01 ADMIN_ORDER'!P2="","BELUM DITETAPKAN",TEXT('01 ADMIN_ORDER'!P2,"dd mmm yyyy")) -> BELUM DITETAPKAN
A22: TARGET SELESAI UPPER | D22: =IF('01 ADMIN_ORDER'!Q2="","BELUM DITETAPKAN",TEXT('01 ADMIN_ORDER'!Q2,"dd mmm yyyy")) -> BELUM DITETAPKAN
A23: ="REFERENSI ASSEMBLY (bukan target upper): "&TEXT('01 ADMIN_ORDER'!M2,"dd mmm yyyy")&" - "&TEXT('01 ADMIN_ORDER'!N2,"dd mmm yyyy") -> REFERENSI ASSEMBLY (bukan target upper): 25 Sep 2026 - 25 Sep 2026
A24: BATCH / LOT | D24: =IF('04 KESIAPAN'!G2="","BELUM DIISI",'04 KESIAPAN'!G2) -> BELUM DIISI
A25: BOM / REVISI | D25: =IF('04 KESIAPAN'!H2="","BELUM DIISI",'04 KESIAPAN'!H2) -> BELUM DIISI
A26: TECH PACK / PATTERN | D26: =IF('04 KESIAPAN'!I2="","BELUM DIISI",'04 KESIAPAN'!I2) -> BELUM DIISI
A27: ROUTING / INSTRUKSI | D27: =IF('04 KESIAPAN'!K2="","BELUM DIISI",'04 KESIAPAN'!K2) -> BELUM DIISI
A28: QC / ACCEPTANCE | D28: =IF('04 KESIAPAN'!L2="","BELUM DIISI",'04 KESIAPAN'!L2) -> BELUM DIISI
A29: PIC PRODUKSI | D29: =IF('04 KESIAPAN'!N2="","BELUM DIISI",'04 KESIAPAN'!N2) -> BELUM DIISI
A30: DISETUJUI OLEH | D30: =IF('04 KESIAPAN'!P2="","BELUM DIISI",'04 KESIAPAN'!P2) -> BELUM DIISI
A31: CATATAN PELAKSANAAN / SERAH TERIMA (isi mengikuti SOP)
A35: Operator: __________________ | E35: QC / Penerima: ________________
A36: Referensi detail sumber: SEPT SPK baris 6 | Catat aktual per transaksi pada 05 AKTUAL.
A39: PROJECT NURA — KARTU KERJA UPPER
A40: ='01 ADMIN_ORDER'!R3 -> DRAFT - PERLU VERIFIKASI
A41: Belum untuk instruksi produksi sampai data dan otorisasi diverifikasi.
A42: NO SPK | C42: ='01 ADMIN_ORDER'!A3 -> 138/10/2 (59)
A43: MODEL / ARTIKEL | C43: ='01 ADMIN_ORDER'!C3&" / "&'01 ADMIN_ORDER'!D3 -> FRONTCOURT LOW / LA6616
A44: PO SUMBER | C44: ='01 ADMIN_ORDER'!E3 -> 903285985 (FGT)
A45: WARNA | C45: ='01 ADMIN_ORDER'!H3 -> EARTH STRATA/OFF WHITE/DARK BROWN
...

Sheet 04 KESIAPAN
A1: No SPK sumber | B1: UOM [ISI] | C1: Sistem ukuran [ISI] | D1: Arti tanda - [ISI] | E1: Jenis pekerjaan / lingkup [ISI] | F1: PO subkontrak terverifikasi [ISI] | G1: Batch / lot [ISI] | H1: BOM + revisi [ISI] | I1: Tech pack / pattern + revisi [ISI] | J1: Approved sample ref [ISI] | K1: Routing / instruksi kerja ref [ISI] | L1: QC / acceptance ref [ISI] | M1: Material readiness [ISI] | N1: PIC produksi [ISI] | O1: Diperiksa oleh [ISI] | P1: Disetujui oleh [ISI] | Q1: Tanggal persetujuan [ISI] | R1: Catatan / kondisi release [ISI]
A2: 137/10/1 (59)
A3: 138/10/2 (59)
A4: 139/10/3 (59)
A5: 140/10/4 (59)
A6: 141/10/5 (59)
A7: 142/10/6 (59)
A8: 143/10/7 (59)
A9: 144/10/8 (59)
A10: 145/10/9 (59)
A11: 146/10/10 (59)
A12: 147/10/11 (59)
A13: 148/10/12 (59)
... A60: 195/10/59 (59)

Sheet 05 AKTUAL
A1: ID transaksi [ISI] | B1: Tanggal / shift [ISI] | C1: No SPK sumber | D1: Batch / bundle [ISI] | E1: Proses [ISI] | F1: Label ukuran [ISI] | G1: Qty masuk [ISI] | H1: Qty baik [ISI] | I1: Qty reject [ISI] | J1: Qty rework [ISI] | K1: Operator / PIC [ISI] | L1: QC / penerima [ISI] | M1: Catatan [ISI]

Sheet 06 KONFIRMASI
A1: ID | B1: Prioritas | C1: Cakupan | D1: Temuan / pertanyaan | E1: Tindakan yang diperlukan | F1: Keputusan / sumber resmi [ISI] | G1: PIC [ISI] | H1: Status
A2: K01 | B2: TINGGI | C2: 59 order | D2: CRD 30 Jul / LPD 14 Jul 2026 pada detail mendahului jadwal Sep–Okt. | E2: Validasi tanggal dan definisi terhadap PO/schedule resmi. | H2: TERBUKA
A3: K02 | B3: TINGGI | C3: Dokumen | D3: OCTOBER ORDER vs SEPT ORDER vs footer September. | E3: Tetapkan periode, tanggal issue, revisi dan nomor dokumen. | H3: TERBUKA
A4: K03 | B4: TINGGI | C4: 59 order | D4: Satuan belum eksplisit. | E4: Tetapkan pair/set/piece sesuai PO dan lingkup upper. | H4: TERBUKA
A5: K04 | B5: TINGGI | C5: 29 label size | D5: Sistem ukuran dan tanda - belum didefinisikan. | E5: Konfirmasi buyer US/UK/EU dan arti half size tanpa asumsi. | H5: TERBUKA
A6: K05 | B6: TINGGI | C6: 59 order | D6: BOM/tech pack/pattern/QC/release belum tertelusur. | E6: Isi referensi revisi dan approval pada 04 KESIAPAN. | H6: TERBUKA
A7: K06 | B7: SEDANG | C7: 8 order FGT | D7: FGT masing-masing 9; total 72. | E7: Konfirmasi arti dan apakah tambahan atau termasuk PO. | H7: TERBUKA
A8: K07 | B8: SEDANG | C8: SEP!G36 | D8: Sumber berisi formula =15807-36, bukan teks PO. | E8: Konfirmasi nomor PO subkontrak dari dokumen resmi. | H8: TERBUKA
A9: K08 | B9: SEDANG | C9: Penjadwalan | D9: BUILD/CELL/G/BIG/GNJ/CRD/LPD/PODD belum punya kamus pasti. | E9: Tetapkan pemilik definisi dan mapping field. | H9: TERBUKA
A10: K09 | B10: SEDANG | C10: PART / batch | D10: PART 1/2/3 belum punya distribusi qty/size. | E10: Tetapkan batch/bundle dan jumlah per ukuran. | H10: TERBUKA
A11: K10 | B11: SEDANG | C11: Target upper | D11: Assembly plan bukan otomatis target proses upper. | E11: Admin isi target mulai/selesai upper dari jadwal sah. | H11: TERBUKA
A12: K11 | B12: DIPERBAIKI | C12: Rumus size | D12: Formula sumber sebagian berhenti AM. | E12: Versi baru memakai SUM seluruh 29 ukuran D:AF. | H12: SELESAI LAYOUT
A13: K12 | B13: DIPERBAIKI | C13: Layout | D13: Detail sulit dibaca dan tanggal di luar area cetak. | E13: Versi baru memisah admin/size dan menyediakan kartu operator per halaman. | H13: SELESAI LAYOUT

Sheet 07 SUMBER_ORDER
A1: Sheet asal | B1: Baris asal | C1: No SPK | D1: Build | E1: Model | F1: Artikel | G1: PO (teks) | H1: Warna | I1: Tujuan sumber | J1: G sumber | K1: Qty sumber | L1: Material plan sumber | M1: Assembly mulai sumber | N1: Assembly selesai sumber | O1: AU header sumber | P1: AU nilai sumber | Q1: AV header sumber | R1: AV nilai sumber | S1: PO subkontrak sumber (teks literal) | T1: Total size dihitung independen
A2: SEP | B2: 6 | C2: 137/10/1 (59) | D2: A-19 | E2: FRONTCOURT LOW | F2: LA6616 | G2: 903285985 | H2: EARTH STRATA/OFF WHITE/DARK BROWN | I2: Morocco | J2: M | K2: 155 | L2: 46273 | M2: 46290 | N2: 46290 | O2: LPD (TGL EXPORT) | Q2: PODD | R2: 46309
A3: SEP | B3: 7 | C3: 138/10/2 (59) | D3: A-19 | E3: FRONTCOURT LOW | F3: LA6616 | G3: 903285985 (FGT) | H3: EARTH STRATA/OFF WHITE/DARK BROWN | I3: Morocco | J3: M | K3: 9 | L3: 46273 | M3: 46290 | N3: 46290 | O3: LPD (TGL EXPORT) | Q3: PODD | R3: 46309
A4: SEP | B4: 8 | C4: 139/10/3 (59) | D4: A-19 | E4: FRONTCOURT LOW | F4: LA6616 | G4: 903424679 | H4: EARTH STRATA/OFF WHITE/DARK BROWN | I4: Germany | J4: M | K4: 650 | L4: 46273 | M4: 46290 | N4: 46290 | O4: LPD (TGL EXPORT) | Q4: PODD | R4: 46309
A5: SEP | B5: 9 | C5: 140/10/4 (59) | D5: A-19 | E5: FRONTCOURT LOW | F5: LA6616 | G5: 903424725 | H5: EARTH STRATA/OFF WHITE/DARK BROWN | I5: Germany | J5: M | K5: 650 | L5: 46273 | M5: 46290 | N5: 46293 | O5: LPD (TGL EXPORT) | Q5: PODD | R5: 46309
A6: SEP | B6: 10 | C6: 141/10/5 (59) | D6: A-19 | E6: FRONTCOURT LOW | F6: LA6617 | G6: 903271565 | H6: OLIVE TWO/OFF WHITE/OLIVE THREE | I6: Morocco | J6: M | K6: 181 | L6: 46273 | M6: 46293 | N6: 46293 | O6: LPD (TGL EXPORT) | Q6: PODD | R6: 46309
A7: SEP | B7: 11 | C7: 142/10/6 (59) | D7: A-19 | E7: FRONTCOURT LOW | F7: LA6617 | G7: 903271565 (FGT) | H7: OLIVE TWO/OFF WHITE/OLIVE THREE | I7: Morocco | J7: M | K7: 9 | L7: 46273 | M7: 46293 | N7: 46293 | O7: LPD (TGL EXPORT) | Q7: PODD | R7: 46309
A8: SEP | B8: 12 | C8: 143/10/7 (59) | D8: A-19 | E8: FRONTCOURT LOW | F8: LA6617 | G8: 903079277 | H8: OLIVE TWO/OFF WHITE/OLIVE THREE | I8: USA | J8: M | K8: 6120 | L8: 46273 | M8: 46293 | N8: 46302 | O8: LPD (TGL EXPORT) | Q8: PODD | R8: 46309
A9: SEP | B9: 13 | C9: 144/10/8 (59) | D9: A-19 | E9: FRONTCOURT LOW | F9: LA6606 | G9: 903279874 | H9: CORE BLACK/CORE BLACK/GREY FIVE | I9: Peru | J9: M | K9: 440 | L9: 46280 | M9: 46302 | N9: 46302 | O9: LPD (TGL EXPORT) | Q9: PODD | R9: 46309
A10: SEP | B10: 14 | C10: 145/10/9 (59) | D10: A-19 | E10: FRONTCOURT LOW | F10: LA6606 | G10: 903279874 (FGT) | H10: CORE BLACK/CORE BLACK/GREY FIVE | I10: Peru | J10: M | K10: 9 | L10: 46280 | M10: 46302 | N10: 46302 | O10: LPD (TGL EXPORT) | Q10: PODD | R10: 46309
A11: SEP | B11: 15 | C11: 146/10/10 (59) | D11: A-19 | E11: FRONTCOURT LOW | F11: LA6606 | G11: 903284277 | H11: CORE BLACK/CORE BLACK/GREY FIVE | I11: Germany (Zalando) | J11: M | K11: 645 | L11: 46280 | M11: 46302 | N11: 46303 | O11: LPD (TGL EXPORT) | Q11: PODD | R11: 46309
A12: SEP | B12: 16 | C12: 147/10/11 (59) | D12: A-19 | E12: FRONTCOURT LOW | F12: LA6604 | G12: 903410228 | H12: CORE BLACK/FTWR WHITE/CORE BLACK | I12: Israel | J12: M | K12: 241 | L12: 46280 | M12: 46303 | N12: 46303 | O12: LPD (TGL EXPORT) | Q12: PODD | R12: 46317
A13: SEP | B13: 17 | C13: 148/10/12 (59) | D13: A-19 | E13: FRONTCOURT LOW | F13: LA6604 | G13: 903410228 (FGT) | H13: CORE BLACK/FTWR WHITE/CORE BLACK | I13: Israel | J13: M | K13: 9 | L13: 46280 | M13: 46303 | N13: 46303 | O13: LPD (TGL EXPORT) | Q13: PODD | R13: 46317
... A31: SEP | B31: 35 | C31: 166/10/30 (59) | D31: A-19 | E31: FRONTCOURT LOW | F31: KH5441 | G31: 903408939 | H31: FTWR WHITE/CORE BLACK/CORE BLACK | I31: Germany (Zalando) | J31: M | K31: 607 | L31: 46289 | M31: 46314 | N31: 46314 | O31: LPD (TGL EXPORT) | Q31: PODD | R31: 46332
A32: SEP | B32: 36 | C32: 167/10/31 (59) | D32: A-19 | E32: FRONTCOURT LOW | F32: LA6606 | G32: 903394951 | H32: CORE BLACK/CORE BLACK/GREY FIVE | I32: United Kingdom | J32: M | K32: 435 | L32: 46289 | M32: 46314 | N32: 46315 | O32: LPD (TGL EXPORT) | Q32: PODD | R32: 46332 | S32: =15807-36
A33: SEP | B33: 37 | C33: 168/10/32 (59) | D33: A-19 | E33: FRONTCOURT LOW | F33: LA6606 | G33: 903412031 | H33: CORE BLACK/CORE BLACK/GREY FIVE | I33: Germany (Zalando) | J33: M | K33: 1100 | L33: 46289 | M33: 46315 | N33: 46316 | O33: LPD (TGL EXPORT) | Q33: PODD | R33: 46332
A34: SEP | B34: 38 | C34: 169/10/33 (59) | D34: A-19 | E34: FRONTCOURT LOW | F34: LA6617 | G34: 903403418 | H34: OLIVE TWO/OFF WHITE/OLIVE THREE | I34: United Kingdom | J34: M | K34: 365 | L34: 46289 | M34: 46316 | N34: 46316 | O34: LPD (TGL EXPORT) | Q34: PODD | R34: 46332
A35: SEP | B35: 39 | C35: 170/10/34 (59) | D35: A-19 | E35: FRONTCOURT LOW | F35: LA6617 | G35: 903277029 | H35: OLIVE TWO/OFF WHITE/OLIVE THREE | I35: Italy (Zalando) | J35: M | K35: 370 | L35: 46289 | M35: 46316 | N35: 46317 | O35: LPD (TGL EXPORT) | Q35: PODD | R35: 46332
A36: SEP | B36: 40 | C36: 171/10/35 (59) | D36: A-19 | E36: FRONTCOURT LOW | F36: LA6617 | G36: 903417865 | H36: OLIVE TWO/OFF WHITE/OLIVE THREE | I36: Germany (Zalando) | J36: M | K36: 618 | L36: 46289 | M36: 46317 | N36: 46317 | O36: LPD (TGL EXPORT) | Q36: PODD | R36: 46332
A37: SEP | B37: 46 | C37: 172/10/36 (59) | D37: B-19 | E37: FRONTCOURT LOW | F37: LA6615 | G37: 903399221 | H37: FTWR WHITE/CORE BLACK/GREY ONE | I37: Brazil | J37: M | K37: 351 | L37: 46275 | M37: 46295 | N37: 46295 | O37: LPD (TGL EXPORT) | Q37: PODD | R37: 46309
A38: SEP | B38: 47 | C38: 173/10/37 (59) | D38: B-19 | E38: FRONTCOURT LOW | F38: LA6615 | G38: 903410761 | H38: FTWR WHITE/CORE BLACK/GREY ONE | I38: Chile | J38: M | K38: 525 | L38: 46275 | M38: 46295 | N38: 46295 | O38: LPD (TGL EXPORT) | Q38: PODD | R38: 46309
A39: SEP | B39: 48 | C39: 174/10/38 (59) | D39: B-19 | E39: FRONTCOURT LOW | F39: LA6615 | G39: 903409848 | H39: FTWR WHITE/CORE BLACK/GREY ONE | I39: Peru | J39: M | K39: 852 | L39: 46275 | M39: 46295 | N39: 46296 | O39: LPD (TGL EXPORT) | Q39: PODD | R39: 46309
A40: SEP | B40: 49 | C40: 175/10/39 (59) | D40: B-19 | E40: FRONTCOURT LOW | F40: LA6607 | G40: 903153457 | H40: FTWR WHITE/FTWR WHITE/GREY TWO | I40: Germany | J40: M | K40: 650 | L40: 46275 | M40: 46296 | N40: 46297 | O40: LPD (TGL EXPORT) | Q40: PODD | R40: 46309
A41: SEP | B41: 50 | C41: 176/10/40 (59) | D41: B-19 | E41: FRONTCOURT LOW | F41: LA6607 | G41: 903153502 | H41: FTWR WHITE/FTWR WHITE/GREY TWO | I41: Germany | J41: M | K41: 650 | L41: 46275 | M41: 46297 | N41: 46300 | O41: LPD (TGL EXPORT) | Q41: PODD | R41: 46309
A42: SEP | B42: 51 | C42: 177/10/41 (59) | D42: B-19 | E42: FRONTCOURT LOW | F42: LA6607 | G42: 903410013 | H42: FTWR WHITE/FTWR WHITE/GREY TWO | I42: Peru | J42: M | K42: 300 | L42: 46275 | M42: 46300 | N42: 46300 | O42: LPD (TGL EXPORT) | Q42: PODD | R42: 46309
A43: SEP | B43: 52 | C43: 178/10/42 (59) | D43: B-19 | E43: FRONTCOURT LOW | F43: LA6614 | G43: 903409634 | H43: CORE BLACK/FTWR WHITE/GUM M2 | I43: Colombia | J43: M | K43: 300 | L43: 46275 | M43: 46300 | N43: 46300 | O43: LPD (TGL EXPORT) | Q43: PODD | R43: 46309
A44: SEP | B44: 53 | C44: 179/10/43 (59) | D44: B-19 | E44: FRONTCOURT LOW | F44: LA6614 | G44: 903390412 | H44: CORE BLACK/FTWR WHITE/GUM M2 | I44: Argentina | J44: M | K44: 360 | L44: 46275 | M44: 46300 | N44: 46301 | O44: LPD (TGL EXPORT) | Q44: PODD | R44: 46309
... A60: SEP | B60: 69 | C60: 195/10/59 (59) | D60: B-19 | E60: FRONTCOURT LOW | F60: LA6615 | G60: 903500993 (FGT) | H60: FTWR WHITE/CORE BLACK/GREY ONE | I60: Germany | J60: M | K60: 9 | L60: 46289 | M60: 46317 | N60: 46317 | O60: LPD (TGL EXPORT) | Q60: PODD | R60: 46332
A61: SEPT SPK | B61: 6 | C61: 137/10/1 (59) | D61: A-19 | E61: FRONTCOURT LOW | F61: LA6616 | G61: 903285985 | H61: EARTH STRATA/OFF WHITE/DARK BROWN | I61: Morocco | J61: M | K61: 155 | O61: CRD (TGL EXPORT) | P61: 46233 | Q61: LPD (TGL EXPORT) | R61: 46217 | T61: 155
A62: SEPT SPK | B62: 14 | C62: 138/10/2 (59) | D62: A-19 | E62: FRONTCOURT LOW | F62: LA6616 | G62: 903285985 (FGT) | H62: EARTH STRATA/OFF WHITE/DARK BROWN | I62: Morocco | J62: M | K62: 9 | O62: CRD (TGL EXPORT) | P62: 46233 | Q62: LPD (TGL EXPORT) | R62: 46217 | T62: 9
A63: SEPT SPK | B63: 19 | C63: 139/10/3 (59) | D63: A-19 | E63: FRONTCOURT LOW | F63: LA6616 | G63: 903424679 | H63: EARTH STRATA/OFF WHITE/DARK BROWN | I63: Germany | J63: M | K63: 650 | O63: CRD (TGL EXPORT) | P63: 46233 | Q63: LPD (TGL EXPORT) | R63: 46217 | T63: 650
A64: SEPT SPK | B64: 26 | C64: 140/10/4 (59) | D64: A-19 | E64: FRONTCOURT LOW | F64: LA6616 | G64: 903424725 | H64: EARTH STRATA/OFF WHITE/DARK BROWN | I64: Germany | J64: M | K64: 650 | O64: CRD (TGL EXPORT) | P64: 46233 | Q64: LPD (TGL EXPORT) | R64: 46217 | T64: 650
A65: SEPT SPK | B65: 31 | C65: 141/10/5 (59) | D65: A-19 | E65: FRONTCOURT LOW | F65: LA6617 | G65: 903271565 | H65: OLIVE TWO/OFF WHITE/OLIVE THREE | I65: Morocco | J65: M | K65: 181 | O65: CRD (TGL EXPORT) | P65: 46233 | Q65: LPD (TGL EXPORT) | R65: 46217 | T65: 181
A66: SEPT SPK | B66: 36 | C66: 142/10/6 (59) | D66: A-19 | E66: FRONTCOURT LOW | F66: LA6617 | G66: 903271565 (FGT) | H66: OLIVE TWO/OFF WHITE/OLIVE THREE | I66: Morocco | J66: M | K66: 9 | O66: CRD (TGL EXPORT) | P66: 46233 | Q66: LPD (TGL EXPORT) | R66: 46217 | T66: 9
A67: SEPT SPK | B67: 41 | C67: 143/10/7 (59) | D67: A-19 | E67: FRONTCOURT LOW | F67: LA6617 | G67: 903079277 | H67: OLIVE TWO/OFF WHITE/OLIVE THREE | I67: USA | J67: M | K67: 6120 | O67: CRD (TGL EXPORT) | P67: 46233 | Q67: LPD (TGL EXPORT) | R67: 46217 | T67: 6120
A68: SEPT SPK | B68: 46 | C68: 144/10/8 (59) | D68: A-19 | E68: FRONTCOURT LOW | F68: LA6606 | G68: 903279874 | H68: CORE BLACK/CORE BLACK/GREY FIVE | I68: Peru | J68: M | K68: 440 | O68: CRD (TGL EXPORT) | P68: 46233 | Q68: LPD (TGL EXPORT) | R68: 46217 | T68: 440
A69: SEPT SPK | B69: 51 | C69: 145/10/9 (59) | D69: A-19 | E69: FRONTCOURT LOW | F69: LA6606 | G69: 903279874 (FGT) | H69: CORE BLACK/CORE BLACK/GREY FIVE | I69: Peru | J69: M | K69: 9 | O69: CRD (TGL EXPORT) | P69: 46233 | Q69: LPD (TGL EXPORT) | R69: 46217 | T69: 9
A70: SEPT SPK | B70: 56 | C70: 146/10/10 (59) | D70: A-19 | E70: FRONTCOURT LOW | F70: LA6606 | G70: 903284277 | H70: CORE BLACK/CORE BLACK/GREY FIVE | I70: Germany (Zalando) | J70: M | K70: 645 | O70: CRD (TGL EXPORT) | P70: 46233 | Q70: LPD (TGL EXPORT) | R70: 46217 | T70: 645
A71: SEPT SPK | B71: 63 | C71: 147/10/11 (59) | D71: A-19 | E71: FRONTCOURT LOW | F71: LA6604 | G71: 903410228 | H71: CORE BLACK/FTWR WHITE/CORE BLACK | I71: Israel | J71: M | K71: 241 | O71: CRD (TGL EXPORT) | P71: 46233 | Q71: LPD (TGL EXPORT) | R71: 46217 | T71: 241
A72: SEPT SPK | B72: 71 | C72: 148/10/12 (59) | D72: A-19 | E72: FRONTCOURT LOW | F72: LA6604 | G72: 903410228 (FGT) | H72: CORE BLACK/FTWR WHITE/CORE BLACK | I72: Israel | J72: M | K72: 9 | O72: CRD (TGL EXPORT) | P72: 46233 | Q72: LPD (TGL EXPORT) | R72: 46217 | T72: 9
...

Sheet 08 KAMUS
A1: Field | B1: Definisi / aturan
A2: No SPK sumber | B2: Identifier asli, dipertahankan utuh; bukan nomor baru yang telah disahkan.
A3: Build sumber | B3: A-19/B-19 sesuai file; arti area/line menunggu konfirmasi.
A4: Tujuan / channel | B4: Isi CUSTOMER asli; tidak otomatis nama legal pelanggan.
A5: FGT | B5: Penanda literal PO asli. Makna bisnis belum dipastikan.
A6: UOM | B6: Satuan kuantitas wajib diverifikasi sebelum release.
A7: Sistem ukuran | B7: Tetapkan sistem buyer; label ukuran asli tidak dikonversi otomatis.
A8: Total / selisih size | B8: Total = seluruh 29 kolom size; selisih = total size dikurangi qty order. Nol berarti cocok secara jumlah.
A9: Rencana sumber | B9: Tanggal dari SEP; belum berarti realisasi, material readiness, atau target upper.
A10: Target UPPER | B10: Isian terpisah, bukan hasil tebak dari assembly minus empat hari.
A11: Status dokumen | B11: Versi ini seluruhnya DRAFT. Isi approval tidak otomatis mengubah status atau mengesahkan release.
A12: Material readiness | B12: Catat pemeriksaan ketersediaan, kelengkapan dan mutu; tanggal outgoing saja tidak cukup.
... A18: Nol pada SIZE_RUN | B18: Kolom size yang kosong pada sumber ditampilkan nol untuk memudahkan hitung; bukan menandakan ukuran tersebut disetujui buyer.
